<?xml version="1.0" ?>
<!-- =================================================================================== -->
<!-- |    This document was autogenerated by xacro from ./s1-based-rover.urdf.xacro    | -->
<!-- |    EDITING THIS FILE BY HAND IS NOT RECOMMENDED                                 | -->
<!-- =================================================================================== -->
<robot name="rover">
  <material name="black">
    <color rgba="0.15 0.15 0.15 1.0"/>
  </material>
  <material name="light_grey">
    <color rgba="0.4 0.4 0.4 1.0"/>
  </material>
  <!--<plugin name="gazebo_ros_control" filename="libgazebo_ros_control.so">
      <robotNamespace>/</robotNamespace>
    </plugin>-->
  <!--     <plugin name="nexus_ros_force_based_move" filename="libnexus_ros_force_based_move.so">
      <commandTopic>cmd_vel</commandTopic>
      <odometryTopic>odom</odometryTopic>
      <odometryFrame>odom</odometryFrame>
      <odometryRate>25.0</odometryRate>
      <robotBaseFrame>base_footprint</robotBaseFrame>
      <cmdVelTimeOut>0.25</cmdVelTimeOut>
      <publishOdometryTf>0</publishOdometryTf>
      <yaw_velocity_p_gain>1.0</yaw_velocity_p_gain>
      <x_velocity_p_gain>15.0</x_velocity_p_gain>
      <y_velocity_p_gain>15.0</y_velocity_p_gain>
      <max_x_velocity>0.6</max_x_velocity>
      <max_y_velocity>0.6</max_y_velocity>
      <max_yaw_velocity>0.5</max_yaw_velocity>
    </plugin>
  </gazebo> -->
  <!-- All static links get collapsed down to base_link in Gazebo, so that's
       the one to apply the colour to (in Gazebo 5+). -->
  <gazebo reference="base_footprint">
    <material>Gazebo/Black</material>
    <gravity>true</gravity>
  </gazebo>
  <gazebo reference="chassis">
    <material>Gazebo/Black</material>
  </gazebo>
  <gazebo reference="sprayer_assembly">
    <material>Gazebo/Grey</material>
  </gazebo>
  <gazebo reference="wheel1_shaft">
    <material>Gazebo/Black</material>
  </gazebo>
  <gazebo reference="wheel1">
    <material>=Gazebo/Grey</material>
    <mu1>0.0</mu1>
    <mu2>0.0</mu2>
  </gazebo>
  <gazebo reference="wheel2_shaft">
    <material>Gazebo/Black</material>
  </gazebo>
  <gazebo reference="wheel2">
    <material>=Gazebo/Grey</material>
    <mu1>0.0</mu1>
    <mu2>0.0</mu2>
  </gazebo>
  <gazebo reference="wheel3_shaft">
    <material>Gazebo/Black</material>
  </gazebo>
  <gazebo reference="wheel3">
    <material>=Gazebo/Grey</material>
    <mu1>0.0</mu1>
    <mu2>0.0</mu2>
  </gazebo>
  <gazebo reference="wheel4_shaft">
    <material>Gazebo/Black</material>
  </gazebo>
  <gazebo reference="wheel4">
    <material>=Gazebo/Grey</material>
    <mu1>0.0</mu1>
    <mu2>0.0</mu2>
  </gazebo>
  <link name="world"/>
  <joint name="fixed" type="fixed">
    <parent link="world"/>
    <child link="base_footprint"/>
  </joint>
  <link name="base_footprint">
    <collision>
      <origin rpy="0 0 0" xyz="0 0 0"/>
      <geometry>
        <box size="0.24486561599999998 0.34297308299999996 0.115788025"/>
      </geometry>
    </collision>
    <inertial>
      <origin rpy="0 0 0" xyz="0 0 0"/>
      <mass value="1"/>
      <inertia ixx="1.0" ixy="0.0" ixz="0.0" iyy="1.0" iyz="0.0" izz="1.0"/>
    </inertial>
  </link>
  <joint name="chassis_joint" type="fixed">
    <origin rpy="0 0 0" xyz="0 0 0.0"/>
    <parent link="base_footprint"/>
    <child link="chassis"/>
  </joint>
  <link name="chassis">
    <visual>
      <geometry>
        <mesh filename="package://mecanum_model/meshes/chassis.stl" scale="0.001 0.001 0.001"/>
      </geometry>
      <material name="black"/>
    </visual>
    <collision>
      <origin rpy="0 0 0" xyz="0 0 0"/>
      <geometry>
        <box size="0.14839953600000003 0.252206665 0.055450001"/>
      </geometry>
    </collision>
    <inertial>
      <origin rpy="0 0 0" xyz="0 0 0"/>
      <mass value="1"/>
      <inertia ixx="1.0" ixy="0.0" ixz="0.0" iyy="1.0" iyz="0.0" izz="1.0"/>
    </inertial>
  </link>
  <joint name="sprayer_joint" type="fixed">
    <origin rpy="0 0 0" xyz="-0.003 -0.14 0.005"/>
    <parent link="chassis"/>
    <child link="sprayer_assembly"/>
  </joint>
  <link name="sprayer_assembly">
    <visual>
      <geometry>
        <mesh filename="package://mecanum_model/meshes/sprayer_assembly.stl" scale="0.001 0.001 0.001"/>
      </geometry>
      <material name="light_grey"/>
    </visual>
  </link>
  <joint name="wheel1_shaft_joint" type="continuous">
    <origin rpy="0 0 0" xyz="-0.065 0.1 0.0"/>
    <axis xyz="1 0 0"/>
    <parent link="chassis"/>
    <child link="wheel1_shaft"/>
  </joint>
  <link name="wheel1_shaft">
    <visual>
      <origin rpy="0 0 0" xyz="0 0 0.0"/>
      <geometry>
        <mesh filename="package://mecanum_model/meshes/wheel_shaft_min.stl" scale="0.001 0.001 0.001"/>
      </geometry>
      <material name="black"/>
    </visual>
    <collision>
      <origin xyz="0 0 0.0"/>
      <geometry>
        <mesh filename="package://mecanum_model/meshes/wheel_shaft_min.stl" scale="0.001 0.001 0.001"/>
      </geometry>
    </collision>
    <inertial>
      <origin rpy="0 0 0" xyz="0 0 0"/>
      <mass value="0.055"/>
      <inertia ixx="0.000021370" ixy="0" ixz="0" iyy="0.000009966" iyz="0" izz="0.000021370"/>
    </inertial>
  </link>
  <joint name="wheel1_wheel_joint" type="fixed">
    <origin rpy="0 0 0" xyz="-0.035 0 0"/>
    <parent link="wheel1_shaft"/>
    <child link="wheel1"/>
  </joint>
  <link name="wheel1">
    <visual>
      <origin rpy="0 0 0" xyz="0 0 0"/>
      <geometry>
        <mesh filename="package://mecanum_model/meshes/wheel_cw.stl" scale="0.001 0.001 0.001"/>
      </geometry>
      <material name="light_grey"/>
    </visual>
    <collision>
      <origin rpy="0 0 0" xyz="0 0 0"/>
      <geometry>
        <cylinder length="0.0505" radius="0.05"/>
      </geometry>
    </collision>
    <inertial>
      <origin rpy="0 0 0" xyz="0 0 0.0"/>
      <mass value="0.3844"/>
      <!-- Inertia based on cylinder -->
      <inertia ixx="0.000324824" ixy="0" ixz="0" iyy="0.000480000" iyz="0" izz="0.000324824"/>
    </inertial>
  </link>
  <joint name="wheel2_shaft_joint" type="continuous">
    <origin rpy="0 0 0" xyz="0.065 0.1 0.0"/>
    <axis xyz="1 0 0"/>
    <parent link="chassis"/>
    <child link="wheel2_shaft"/>
  </joint>
  <link name="wheel2_shaft">
    <visual>
      <origin rpy="0 0 0" xyz="0 0 0.0"/>
      <geometry>
        <mesh filename="package://mecanum_model/meshes/wheel_shaft_max.stl" scale="0.001 0.001 0.001"/>
      </geometry>
      <material name="black"/>
    </visual>
    <collision>
      <origin xyz="0 0 0.0"/>
      <geometry>
        <mesh filename="package://mecanum_model/meshes/wheel_shaft_max.stl" scale="0.001 0.001 0.001"/>
      </geometry>
    </collision>
    <inertial>
      <origin rpy="0 0 0" xyz="0 0 0"/>
      <mass value="0.055"/>
      <inertia ixx="0.000021370" ixy="0" ixz="0" iyy="0.000009966" iyz="0" izz="0.000021370"/>
    </inertial>
  </link>
  <joint name="wheel2_wheel_joint" type="fixed">
    <origin rpy="0 0 0" xyz="0.035 0 0"/>
    <parent link="wheel2_shaft"/>
    <child link="wheel2"/>
  </joint>
  <link name="wheel2">
    <visual>
      <origin rpy="0 0 0" xyz="0 0 0"/>
      <geometry>
        <mesh filename="package://mecanum_model/meshes/wheel_ccw.stl" scale="0.001 0.001 0.001"/>
      </geometry>
      <material name="light_grey"/>
    </visual>
    <collision>
      <origin rpy="0 0 0" xyz="0 0 0"/>
      <geometry>
        <cylinder length="0.0505" radius="0.05"/>
      </geometry>
    </collision>
    <inertial>
      <origin rpy="0 0 0" xyz="0 0 0.0"/>
      <mass value="0.3844"/>
      <!-- Inertia based on cylinder -->
      <inertia ixx="0.000324824" ixy="0" ixz="0" iyy="0.000480000" iyz="0" izz="0.000324824"/>
    </inertial>
  </link>
  <joint name="wheel3_shaft_joint" type="continuous">
    <origin rpy="0 0 0" xyz="0.065 -0.1 0.0"/>
    <axis xyz="1 0 0"/>
    <parent link="chassis"/>
    <child link="wheel3_shaft"/>
  </joint>
  <link name="wheel3_shaft">
    <visual>
      <origin rpy="0 0 0" xyz="0 0 0.0"/>
      <geometry>
        <mesh filename="package://mecanum_model/meshes/wheel_shaft_max.stl" scale="0.001 0.001 0.001"/>
      </geometry>
      <material name="black"/>
    </visual>
    <collision>
      <origin xyz="0 0 0.0"/>
      <geometry>
        <mesh filename="package://mecanum_model/meshes/wheel_shaft_max.stl" scale="0.001 0.001 0.001"/>
      </geometry>
    </collision>
    <inertial>
      <origin rpy="0 0 0" xyz="0 0 0"/>
      <mass value="0.055"/>
      <inertia ixx="0.000021370" ixy="0" ixz="0" iyy="0.000009966" iyz="0" izz="0.000021370"/>
    </inertial>
  </link>
  <joint name="wheel3_wheel_joint" type="fixed">
    <origin rpy="0 0 0" xyz="0.035 0 0"/>
    <parent link="wheel3_shaft"/>
    <child link="wheel3"/>
  </joint>
  <link name="wheel3">
    <visual>
      <origin rpy="0 0 0" xyz="0 0 0"/>
      <geometry>
        <mesh filename="package://mecanum_model/meshes/wheel_cw.stl" scale="0.001 0.001 0.001"/>
      </geometry>
      <material name="light_grey"/>
    </visual>
    <collision>
      <origin rpy="0 0 0" xyz="0 0 0"/>
      <geometry>
        <cylinder length="0.0505" radius="0.05"/>
      </geometry>
    </collision>
    <inertial>
      <origin rpy="0 0 0" xyz="0 0 0.0"/>
      <mass value="0.3844"/>
      <!-- Inertia based on cylinder -->
      <inertia ixx="0.000324824" ixy="0" ixz="0" iyy="0.000480000" iyz="0" izz="0.000324824"/>
    </inertial>
  </link>
  <joint name="wheel4_shaft_joint" type="continuous">
    <origin rpy="0 0 0" xyz="-0.065 -0.1 0.0"/>
    <axis xyz="1 0 0"/>
    <parent link="chassis"/>
    <child link="wheel4_shaft"/>
  </joint>
  <link name="wheel4_shaft">
    <visual>
      <origin rpy="0 0 0" xyz="0 0 0.0"/>
      <geometry>
        <mesh filename="package://mecanum_model/meshes/wheel_shaft_min.stl" scale="0.001 0.001 0.001"/>
      </geometry>
      <material name="black"/>
    </visual>
    <collision>
      <origin xyz="0 0 0.0"/>
      <geometry>
        <mesh filename="package://mecanum_model/meshes/wheel_shaft_min.stl" scale="0.001 0.001 0.001"/>
      </geometry>
    </collision>
    <inertial>
      <origin rpy="0 0 0" xyz="0 0 0"/>
      <mass value="0.055"/>
      <inertia ixx="0.000021370" ixy="0" ixz="0" iyy="0.000009966" iyz="0" izz="0.000021370"/>
    </inertial>
  </link>
  <joint name="wheel4_wheel_joint" type="fixed">
    <origin rpy="0 0 0" xyz="-0.035 0 0"/>
    <parent link="wheel4_shaft"/>
    <child link="wheel4"/>
  </joint>
  <link name="wheel4">
    <visual>
      <origin rpy="0 0 0" xyz="0 0 0"/>
      <geometry>
        <mesh filename="package://mecanum_model/meshes/wheel_ccw.stl" scale="0.001 0.001 0.001"/>
      </geometry>
      <material name="light_grey"/>
    </visual>
    <collision>
      <origin rpy="0 0 0" xyz="0 0 0"/>
      <geometry>
        <cylinder length="0.0505" radius="0.05"/>
      </geometry>
    </collision>
    <inertial>
      <origin rpy="0 0 0" xyz="0 0 0.0"/>
      <mass value="0.3844"/>
      <!-- Inertia based on cylinder -->
      <inertia ixx="0.000324824" ixy="0" ixz="0" iyy="0.000480000" iyz="0" izz="0.000324824"/>
    </inertial>
  </link>
</robot>
