<?xml version="1.0" ?>
<!-- =================================================================================== -->
<!-- |    This document was autogenerated by xacro from ./s1-based-rover.urdf.xacro    | -->
<!-- |    EDITING THIS FILE BY HAND IS NOT RECOMMENDED                                 | -->
<!-- =================================================================================== -->
<robot name="rover">
  <material name="black">
    <color rgba="0.15 0.15 0.15 1.0"/>
  </material>
  <material name="light_grey">
    <color rgba="0.4 0.4 0.4 1.0"/>
  </material>
  <!--<plugin name="gazebo_ros_control" filename="libgazebo_ros_control.so">
      <robotNamespace>/</robotNamespace>
    </plugin>-->
  <!--     <plugin name="nexus_ros_force_based_move" filename="libnexus_ros_force_based_move.so">
      <commandTopic>cmd_vel</commandTopic>
      <odometryTopic>odom</odometryTopic>
      <odometryFrame>odom</odometryFrame>
      <odometryRate>25.0</odometryRate>
      <robotBaseFrame>base_footprint</robotBaseFrame>
      <cmdVelTimeOut>0.25</cmdVelTimeOut>
      <publishOdometryTf>0</publishOdometryTf>
      <yaw_velocity_p_gain>1.0</yaw_velocity_p_gain>
      <x_velocity_p_gain>15.0</x_velocity_p_gain>
      <y_velocity_p_gain>15.0</y_velocity_p_gain>
      <max_x_velocity>0.6</max_x_velocity>
      <max_y_velocity>0.6</max_y_velocity>
      <max_yaw_velocity>0.5</max_yaw_velocity>
    </plugin>
  </gazebo> -->
  <!-- All static links get collapsed down to base_link in Gazebo, so that's
       the one to apply the colour to (in Gazebo 5+). -->
  <gazebo reference="base_footprint">
    <material>Gazebo/Black</material>
  </gazebo>
  <gazebo reference="chassis">
    <material>Gazebo/Black</material>
  </gazebo>
  <gazebo reference="sprayer_assembly">
    <material>Gazebo/Grey</material>
  </gazebo>
  <gazebo reference="wheel1_shaft">
    <material>Gazebo/Black</material>
  </gazebo>
  <gazebo reference="wheel1">
    <material>=Gazebo/Grey</material>
    <mu1>0.0</mu1>
    <mu2>0.0</mu2>
  </gazebo>
  <gazebo reference="wheel2_shaft">
    <material>Gazebo/Black</material>
  </gazebo>
  <gazebo reference="wheel2">
    <material>=Gazebo/Grey</material>
    <mu1>0.0</mu1>
    <mu2>0.0</mu2>
  </gazebo>
  <gazebo reference="wheel3_shaft">
    <material>Gazebo/Black</material>
  </gazebo>
  <gazebo reference="wheel3">
    <material>=Gazebo/Grey</material>
    <mu1>0.0</mu1>
    <mu2>0.0</mu2>
  </gazebo>
  <gazebo reference="wheel4_shaft">
    <material>Gazebo/Black</material>
  </gazebo>
  <gazebo reference="wheel4">
    <material>=Gazebo/Grey</material>
    <mu1>0.0</mu1>
    <mu2>0.0</mu2>
  </gazebo>
  <link name="world"/>
  <joint name="fixed" type="fixed">
    <parent link="world"/>
    <child link="base_footprint"/>
  </joint>
  <link name="base_footprint">
    <collision>
      <origin rpy="0 0 0" xyz="0 0 0"/>
      <geometry>
        <box size="0.24486561599999998 0.302041534 0.102041229"/>
      </geometry>
    </collision>
  </link>
  <joint name="chassis_joint" type="fixed">
    <origin rpy="0 0 0" xyz="0 0 0.0"/>
    <parent link="base_footprint"/>
    <child link="chassis"/>
  </joint>
  <link name="chassis">
    <visual>
      <geometry>
        <mesh filename="file:///home/johnathan/devel/inspectobot/rosrover/install/mecanum_model/share/mecanum_model/meshes/visual/chassis.stl" scale="0.001 0.001 0.001"/>
      </geometry>
      <material name="black"/>
    </visual>
    <collision>
      <origin rpy="0 0 0" xyz="0 0 0"/>
      <geometry>
        <box size="0.14839953600000003 0.252206665 0.055450001"/>
      </geometry>
    </collision>
    <inertial>
      <origin rpy="1.5707963267948966 0 1.5707963267948966" xyz="0 0 0"/>
      <mass value="1.0"/>
      <inertia ixx="0.005556908706776852" ixy="0.0" ixz="0.0" iyy="0.00713588534628646" iyz="0.0" izz="0.0020914270746596087"/>
    </inertial>
  </link>
  <joint name="sprayer_joint" type="fixed">
    <origin rpy="0 0 0" xyz="-0.003 -0.14 0.005"/>
    <parent link="chassis"/>
    <child link="sprayer_assembly"/>
  </joint>
  <link name="sprayer_assembly">
    <visual>
      <geometry>
        <mesh filename="file:///home/johnathan/devel/inspectobot/rosrover/install/mecanum_model/share/mecanum_model/meshes/visual/sprayer_assembly.stl" scale="0.001 0.001 0.001"/>
      </geometry>
      <material name="light_grey"/>
    </visual>
    <collision>
      <origin rpy="0 0 0" xyz="0 0 0"/>
      <geometry>
        <box size="0.144179398 0.069498428 0.096728165"/>
      </geometry>
    </collision>
    <inertial>
      <origin rpy="1.5707963267948966 0 1.5707963267948966" xyz="0 0 0"/>
      <mass value="1.0"/>
      <inertia ixx="0.0011821974498948675" ixy="0.0" ixz="0.0" iyy="0.0021348108585094653" iyz="0.0" izz="0.002512003059325802"/>
    </inertial>
  </link>
  <joint name="wheel1_shaft_joint" type="continuous">
    <origin rpy="0 0 0" xyz="-0.065 0.1 0.0"/>
    <axis xyz="1 0 0"/>
    <parent link="chassis"/>
    <child link="wheel1_shaft"/>
  </joint>
  <link name="wheel1_shaft">
    <visual>
      <origin rpy="0 0 0" xyz="0 0 0.0"/>
      <geometry>
        <mesh filename="file:///home/johnathan/devel/inspectobot/rosrover/install/mecanum_model/share/mecanum_model/meshes/visual/wheel_shaft_min.stl" scale="0.001 0.001 0.001"/>
      </geometry>
      <material name="black"/>
    </visual>
    <collision>
      <origin rpy="1.5707963267948966 0 0" xyz="0 0 0"/>
      <geometry>
        <cylinder length="0.037585724" radius="0.005"/>
      </geometry>
    </collision>
    <inertial>
      <origin rpy="1.5707963267948966 0 0" xyz="0 0 0"/>
      <mass value="1.0"/>
      <inertia ixx="0.00012397388738368133" ixy="0" ixz="0" iyy="0.00012397388738368133" iyz="0" izz="1.25e-05"/>
    </inertial>
  </link>
  <joint name="wheel1_wheel_joint" type="fixed">
    <origin rpy="0 0 0" xyz="-0.035 0 0"/>
    <parent link="wheel1_shaft"/>
    <child link="front_left_wheel_link"/>
  </joint>
  <link name="front_left_wheel_link">
    <visual>
      <origin rpy="0 0 0" xyz="0 0 0"/>
      <geometry>
        <mesh filename="file:///home/johnathan/devel/inspectobot/rosrover/install/mecanum_model/share/mecanum_model/meshes/visual/wheel.dae" scale="-0.001 0.001 0.001"/>
      </geometry>
    </visual>
    <collision>
      <geometry>
        <mesh filename="file:///home/johnathan/devel/inspectobot/rosrover/install/mecanum_model/share/mecanum_model/meshes/collision/wheel.stl" scale="-0.001 0.001 0.001"/>
      </geometry>
    </collision>
    <inertial>
      <origin xyz="0 0 0"/>
      <mass value="2.0"/>
      <inertia ixx="0.042025" ixy="0.0" ixz="0.0" iyy="0.024279" iyz="0.0" izz="0.024279"/>
    </inertial>
  </link>
  <gazebo reference="front_left_wheel_link">
    <mu1 value="0.6"/>
    <mu2 value="0.6"/>
    <kp value="10000000.0"/>
    <kd value="1.0"/>
    <fdir1 value="0 1 0"/>
  </gazebo>
  <link name="front_left_roller15_link">
    <visual>
      <origin rpy="0 0 0" xyz="0 0 0"/>
      <geometry>
        <mesh filename="file:///home/johnathan/devel/inspectobot/rosrover/install/mecanum_model/share/mecanum_model/meshes/visual/roller.dae" scale="0.001 0.001 0.001"/>
      </geometry>
    </visual>
    <collision>
      <geometry>
        <mesh filename="file:///home/johnathan/devel/inspectobot/rosrover/install/mecanum_model/share/mecanum_model/meshes/collision/roller.stl" scale="1 1 1"/>
      </geometry>
    </collision>
    <inertial>
      <origin xyz="0 0 0"/>
      <mass value="0.3"/>
      <inertia ixx="0.00024000" ixy="0.0" ixz="0.0" iyy="0.00076000" iyz="0.0" izz="0.00076000"/>
    </inertial>
  </link>
  <joint name="front_left_roller15_joint" type="continuous">
    <origin rpy="0.5619350361043127 -0.7022987807291682 0.38630030387691144" xyz="0 0.04088115922950639 -0.018201464777642055"/>
    <parent link="front_left_wheel_link"/>
    <child link="front_left_roller15_link"/>
    <dynamics damping="0.001" friction="0.0001"/>
  </joint>
  <transmission name="${name}_roller15_trans">
    <type>transmission_interface/SimpleTransmission</type>
    <joint name="front_left_roller15_joint">
      <hardwareInterface>hardware_interface/EffortJointInterface</hardwareInterface>
    </joint>
    <actuator name="front_left_roller15_motor">
      <hardwareInterface>hardware_interface/EffortJointInterface</hardwareInterface>
      <mechanismReduction>1</mechanismReduction>
    </actuator>
  </transmission>
  <gazebo reference="front_left_roller15_link">
    <mu1 value="0.8"/>
    <mu2 value="0.8"/>
    <kp value="10000000.0"/>
    <kd value="1.0"/>
    <fdir1 value="0 1 0"/>
  </gazebo>
  <link name="front_left_roller14_link">
    <visual>
      <origin rpy="0 0 0" xyz="0 0 0"/>
      <geometry>
        <mesh filename="file:///home/johnathan/devel/inspectobot/rosrover/install/mecanum_model/share/mecanum_model/meshes/visual/roller.dae" scale="0.001 0.001 0.001"/>
      </geometry>
    </visual>
    <collision>
      <geometry>
        <mesh filename="file:///home/johnathan/devel/inspectobot/rosrover/install/mecanum_model/share/mecanum_model/meshes/collision/roller.stl" scale="1 1 1"/>
      </geometry>
    </collision>
    <inertial>
      <origin xyz="0 0 0"/>
      <mass value="0.3"/>
      <inertia ixx="0.00024000" ixy="0.0" ixz="0.0" iyy="0.00076000" iyz="0.0" izz="0.00076000"/>
    </inertial>
  </link>
  <joint name="front_left_roller14_joint" type="continuous">
    <origin rpy="1.0038406803226874 -0.4928592704898482 0.6390993414905143" xyz="0 0.029943594634558885 -0.03325573094011341"/>
    <parent link="front_left_wheel_link"/>
    <child link="front_left_roller14_link"/>
    <dynamics damping="0.001" friction="0.0001"/>
  </joint>
  <transmission name="${name}_roller14_trans">
    <type>transmission_interface/SimpleTransmission</type>
    <joint name="front_left_roller14_joint">
      <hardwareInterface>hardware_interface/EffortJointInterface</hardwareInterface>
    </joint>
    <actuator name="front_left_roller14_motor">
      <hardwareInterface>hardware_interface/EffortJointInterface</hardwareInterface>
      <mechanismReduction>1</mechanismReduction>
    </actuator>
  </transmission>
  <gazebo reference="front_left_roller14_link">
    <mu1 value="0.8"/>
    <mu2 value="0.8"/>
    <kp value="10000000.0"/>
    <kd value="1.0"/>
    <fdir1 value="0 1 0"/>
  </gazebo>
  <link name="front_left_roller13_link">
    <visual>
      <origin rpy="0 0 0" xyz="0 0 0"/>
      <geometry>
        <mesh filename="file:///home/johnathan/devel/inspectobot/rosrover/install/mecanum_model/share/mecanum_model/meshes/visual/roller.dae" scale="0.001 0.001 0.001"/>
      </geometry>
    </visual>
    <collision>
      <geometry>
        <mesh filename="file:///home/johnathan/devel/inspectobot/rosrover/install/mecanum_model/share/mecanum_model/meshes/collision/roller.stl" scale="1 1 1"/>
      </geometry>
    </collision>
    <inertial>
      <origin xyz="0 0 0"/>
      <mass value="0.3"/>
      <inertia ixx="0.00024000" ixy="0.0" ixz="0.0" iyy="0.00076000" iyz="0.0" izz="0.00076000"/>
    </inertial>
  </link>
  <joint name="front_left_roller13_joint" type="continuous">
    <origin rpy="1.3449626171032882 -0.22028527385474703 0.7603177925108144" xyz="0 0.013828510498278887 -0.04255977910420812"/>
    <parent link="front_left_wheel_link"/>
    <child link="front_left_roller13_link"/>
    <dynamics damping="0.001" friction="0.0001"/>
  </joint>
  <transmission name="${name}_roller13_trans">
    <type>transmission_interface/SimpleTransmission</type>
    <joint name="front_left_roller13_joint">
      <hardwareInterface>hardware_interface/EffortJointInterface</hardwareInterface>
    </joint>
    <actuator name="front_left_roller13_motor">
      <hardwareInterface>hardware_interface/EffortJointInterface</hardwareInterface>
      <mechanismReduction>1</mechanismReduction>
    </actuator>
  </transmission>
  <gazebo reference="front_left_roller13_link">
    <mu1 value="0.8"/>
    <mu2 value="0.8"/>
    <kp value="10000000.0"/>
    <kd value="1.0"/>
    <fdir1 value="0 1 0"/>
  </gazebo>
  <link name="front_left_roller12_link">
    <visual>
      <origin rpy="0 0 0" xyz="0 0 0"/>
      <geometry>
        <mesh filename="file:///home/johnathan/devel/inspectobot/rosrover/install/mecanum_model/share/mecanum_model/meshes/visual/roller.dae" scale="0.001 0.001 0.001"/>
      </geometry>
    </visual>
    <collision>
      <geometry>
        <mesh filename="file:///home/johnathan/devel/inspectobot/rosrover/install/mecanum_model/share/mecanum_model/meshes/collision/roller.stl" scale="1 1 1"/>
      </geometry>
    </collision>
    <inertial>
      <origin xyz="0 0 0"/>
      <mass value="0.3"/>
      <inertia ixx="0.00024000" ixy="0.0" ixz="0.0" iyy="0.00076000" iyz="0.0" izz="0.00076000"/>
    </inertial>
  </link>
  <joint name="front_left_roller12_joint" type="continuous">
    <origin rpy="-1.4966127917301506 0.07398025001120935 0.7826515949744619" xyz="0 -0.004677648731227488 -0.044504854817730234"/>
    <parent link="front_left_wheel_link"/>
    <child link="front_left_roller12_link"/>
    <dynamics damping="0.001" friction="0.0001"/>
  </joint>
  <transmission name="${name}_roller12_trans">
    <type>transmission_interface/SimpleTransmission</type>
    <joint name="front_left_roller12_joint">
      <hardwareInterface>hardware_interface/EffortJointInterface</hardwareInterface>
    </joint>
    <actuator name="front_left_roller12_motor">
      <hardwareInterface>hardware_interface/EffortJointInterface</hardwareInterface>
      <mechanismReduction>1</mechanismReduction>
    </actuator>
  </transmission>
  <gazebo reference="front_left_roller12_link">
    <mu1 value="0.8"/>
    <mu2 value="0.8"/>
    <kp value="10000000.0"/>
    <kd value="1.0"/>
    <fdir1 value="0 1 0"/>
  </gazebo>
  <link name="front_left_roller11_link">
    <visual>
      <origin rpy="0 0 0" xyz="0 0 0"/>
      <geometry>
        <mesh filename="file:///home/johnathan/devel/inspectobot/rosrover/install/mecanum_model/share/mecanum_model/meshes/visual/roller.dae" scale="0.001 0.001 0.001"/>
      </geometry>
    </visual>
    <collision>
      <geometry>
        <mesh filename="file:///home/johnathan/devel/inspectobot/rosrover/install/mecanum_model/share/mecanum_model/meshes/collision/roller.stl" scale="1 1 1"/>
      </geometry>
    </collision>
    <inertial>
      <origin xyz="0 0 0"/>
      <mass value="0.3"/>
      <inertia ixx="0.00024000" ixy="0.0" ixz="0.0" iyy="0.00076000" iyz="0.0" izz="0.00076000"/>
    </inertial>
  </link>
  <joint name="front_left_roller11_joint" type="continuous">
    <origin rpy="-1.1831996401397156 0.3613671239067081 0.7137243789447655" xyz="0 -0.02237500000000002 -0.038754636819353615"/>
    <parent link="front_left_wheel_link"/>
    <child link="front_left_roller11_link"/>
    <dynamics damping="0.001" friction="0.0001"/>
  </joint>
  <transmission name="${name}_roller11_trans">
    <type>transmission_interface/SimpleTransmission</type>
    <joint name="front_left_roller11_joint">
      <hardwareInterface>hardware_interface/EffortJointInterface</hardwareInterface>
    </joint>
    <actuator name="front_left_roller11_motor">
      <hardwareInterface>hardware_interface/EffortJointInterface</hardwareInterface>
      <mechanismReduction>1</mechanismReduction>
    </actuator>
  </transmission>
  <gazebo reference="front_left_roller11_link">
    <mu1 value="0.8"/>
    <mu2 value="0.8"/>
    <kp value="10000000.0"/>
    <kd value="1.0"/>
    <fdir1 value="0 1 0"/>
  </gazebo>
  <link name="front_left_roller10_link">
    <visual>
      <origin rpy="0 0 0" xyz="0 0 0"/>
      <geometry>
        <mesh filename="file:///home/johnathan/devel/inspectobot/rosrover/install/mecanum_model/share/mecanum_model/meshes/visual/roller.dae" scale="0.001 0.001 0.001"/>
      </geometry>
    </visual>
    <collision>
      <geometry>
        <mesh filename="file:///home/johnathan/devel/inspectobot/rosrover/install/mecanum_model/share/mecanum_model/meshes/collision/roller.stl" scale="1 1 1"/>
      </geometry>
    </collision>
    <inertial>
      <origin xyz="0 0 0"/>
      <mass value="0.3"/>
      <inertia ixx="0.00024000" ixy="0.0" ixz="0.0" iyy="0.00076000" iyz="0.0" izz="0.00076000"/>
    </inertial>
  </link>
  <joint name="front_left_roller10_joint" type="continuous">
    <origin rpy="-0.7989541677433551 0.6090169187607924 0.5313896516603533" xyz="0 -0.0362035104982789 -0.02630339004008817"/>
    <parent link="front_left_wheel_link"/>
    <child link="front_left_roller10_link"/>
    <dynamics damping="0.001" friction="0.0001"/>
  </joint>
  <transmission name="${name}_roller10_trans">
    <type>transmission_interface/SimpleTransmission</type>
    <joint name="front_left_roller10_joint">
      <hardwareInterface>hardware_interface/EffortJointInterface</hardwareInterface>
    </joint>
    <actuator name="front_left_roller10_motor">
      <hardwareInterface>hardware_interface/EffortJointInterface</hardwareInterface>
      <mechanismReduction>1</mechanismReduction>
    </actuator>
  </transmission>
  <gazebo reference="front_left_roller10_link">
    <mu1 value="0.8"/>
    <mu2 value="0.8"/>
    <kp value="10000000.0"/>
    <kd value="1.0"/>
    <fdir1 value="0 1 0"/>
  </gazebo>
  <link name="front_left_roller9_link">
    <visual>
      <origin rpy="0 0 0" xyz="0 0 0"/>
      <geometry>
        <mesh filename="file:///home/johnathan/devel/inspectobot/rosrover/install/mecanum_model/share/mecanum_model/meshes/visual/roller.dae" scale="0.001 0.001 0.001"/>
      </geometry>
    </visual>
    <collision>
      <geometry>
        <mesh filename="file:///home/johnathan/devel/inspectobot/rosrover/install/mecanum_model/share/mecanum_model/meshes/collision/roller.stl" scale="1 1 1"/>
      </geometry>
    </collision>
    <inertial>
      <origin xyz="0 0 0"/>
      <mass value="0.3"/>
      <inertia ixx="0.00024000" ixy="0.0" ixz="0.0" iyy="0.00076000" iyz="0.0" izz="0.00076000"/>
    </inertial>
  </link>
  <joint name="front_left_roller9_joint" type="continuous">
    <origin rpy="-0.29200750368454736 0.7637777909460687 0.20499125187874406" xyz="0 -0.043772105132837795 -0.009304048164094738"/>
    <parent link="front_left_wheel_link"/>
    <child link="front_left_roller9_link"/>
    <dynamics damping="0.001" friction="0.0001"/>
  </joint>
  <transmission name="${name}_roller9_trans">
    <type>transmission_interface/SimpleTransmission</type>
    <joint name="front_left_roller9_joint">
      <hardwareInterface>hardware_interface/EffortJointInterface</hardwareInterface>
    </joint>
    <actuator name="front_left_roller9_motor">
      <hardwareInterface>hardware_interface/EffortJointInterface</hardwareInterface>
      <mechanismReduction>1</mechanismReduction>
    </actuator>
  </transmission>
  <gazebo reference="front_left_roller9_link">
    <mu1 value="0.8"/>
    <mu2 value="0.8"/>
    <kp value="10000000.0"/>
    <kd value="1.0"/>
    <fdir1 value="0 1 0"/>
  </gazebo>
  <link name="front_left_roller8_link">
    <visual>
      <origin rpy="0 0 0" xyz="0 0 0"/>
      <geometry>
        <mesh filename="file:///home/johnathan/devel/inspectobot/rosrover/install/mecanum_model/share/mecanum_model/meshes/visual/roller.dae" scale="0.001 0.001 0.001"/>
      </geometry>
    </visual>
    <collision>
      <geometry>
        <mesh filename="file:///home/johnathan/devel/inspectobot/rosrover/install/mecanum_model/share/mecanum_model/meshes/collision/roller.stl" scale="1 1 1"/>
      </geometry>
    </collision>
    <inertial>
      <origin xyz="0 0 0"/>
      <mass value="0.3"/>
      <inertia ixx="0.00024000" ixy="0.0" ixz="0.0" iyy="0.00076000" iyz="0.0" izz="0.00076000"/>
    </inertial>
  </link>
  <joint name="front_left_roller8_joint" type="continuous">
    <origin rpy="0.2920075036845471 0.7637777909460687 -0.20499125187874387" xyz="0 -0.0437721051328378 0.00930404816409473"/>
    <parent link="front_left_wheel_link"/>
    <child link="front_left_roller8_link"/>
    <dynamics damping="0.001" friction="0.0001"/>
  </joint>
  <transmission name="${name}_roller8_trans">
    <type>transmission_interface/SimpleTransmission</type>
    <joint name="front_left_roller8_joint">
      <hardwareInterface>hardware_interface/EffortJointInterface</hardwareInterface>
    </joint>
    <actuator name="front_left_roller8_motor">
      <hardwareInterface>hardware_interface/EffortJointInterface</hardwareInterface>
      <mechanismReduction>1</mechanismReduction>
    </actuator>
  </transmission>
  <gazebo reference="front_left_roller8_link">
    <mu1 value="0.8"/>
    <mu2 value="0.8"/>
    <kp value="10000000.0"/>
    <kd value="1.0"/>
    <fdir1 value="0 1 0"/>
  </gazebo>
  <link name="front_left_roller7_link">
    <visual>
      <origin rpy="0 0 0" xyz="0 0 0"/>
      <geometry>
        <mesh filename="file:///home/johnathan/devel/inspectobot/rosrover/install/mecanum_model/share/mecanum_model/meshes/visual/roller.dae" scale="0.001 0.001 0.001"/>
      </geometry>
    </visual>
    <collision>
      <geometry>
        <mesh filename="file:///home/johnathan/devel/inspectobot/rosrover/install/mecanum_model/share/mecanum_model/meshes/collision/roller.stl" scale="1 1 1"/>
      </geometry>
    </collision>
    <inertial>
      <origin xyz="0 0 0"/>
      <mass value="0.3"/>
      <inertia ixx="0.00024000" ixy="0.0" ixz="0.0" iyy="0.00076000" iyz="0.0" izz="0.00076000"/>
    </inertial>
  </link>
  <joint name="front_left_roller7_joint" type="continuous">
    <origin rpy="0.7989541677433554 0.6090169187607923 -0.5313896516603536" xyz="0 -0.03620351049827889 0.026303390040088175"/>
    <parent link="front_left_wheel_link"/>
    <child link="front_left_roller7_link"/>
    <dynamics damping="0.001" friction="0.0001"/>
  </joint>
  <transmission name="${name}_roller7_trans">
    <type>transmission_interface/SimpleTransmission</type>
    <joint name="front_left_roller7_joint">
      <hardwareInterface>hardware_interface/EffortJointInterface</hardwareInterface>
    </joint>
    <actuator name="front_left_roller7_motor">
      <hardwareInterface>hardware_interface/EffortJointInterface</hardwareInterface>
      <mechanismReduction>1</mechanismReduction>
    </actuator>
  </transmission>
  <gazebo reference="front_left_roller7_link">
    <mu1 value="0.8"/>
    <mu2 value="0.8"/>
    <kp value="10000000.0"/>
    <kd value="1.0"/>
    <fdir1 value="0 1 0"/>
  </gazebo>
  <link name="front_left_roller6_link">
    <visual>
      <origin rpy="0 0 0" xyz="0 0 0"/>
      <geometry>
        <mesh filename="file:///home/johnathan/devel/inspectobot/rosrover/install/mecanum_model/share/mecanum_model/meshes/visual/roller.dae" scale="0.001 0.001 0.001"/>
      </geometry>
    </visual>
    <collision>
      <geometry>
        <mesh filename="file:///home/johnathan/devel/inspectobot/rosrover/install/mecanum_model/share/mecanum_model/meshes/collision/roller.stl" scale="1 1 1"/>
      </geometry>
    </collision>
    <inertial>
      <origin xyz="0 0 0"/>
      <mass value="0.3"/>
      <inertia ixx="0.00024000" ixy="0.0" ixz="0.0" iyy="0.00076000" iyz="0.0" izz="0.00076000"/>
    </inertial>
  </link>
  <joint name="front_left_roller6_joint" type="continuous">
    <origin rpy="1.1831996401397162 0.3613671239067076 -0.7137243789447657" xyz="0 -0.02237499999999999 0.03875463681935363"/>
    <parent link="front_left_wheel_link"/>
    <child link="front_left_roller6_link"/>
    <dynamics damping="0.001" friction="0.0001"/>
  </joint>
  <transmission name="${name}_roller6_trans">
    <type>transmission_interface/SimpleTransmission</type>
    <joint name="front_left_roller6_joint">
      <hardwareInterface>hardware_interface/EffortJointInterface</hardwareInterface>
    </joint>
    <actuator name="front_left_roller6_motor">
      <hardwareInterface>hardware_interface/EffortJointInterface</hardwareInterface>
      <mechanismReduction>1</mechanismReduction>
    </actuator>
  </transmission>
  <gazebo reference="front_left_roller6_link">
    <mu1 value="0.8"/>
    <mu2 value="0.8"/>
    <kp value="10000000.0"/>
    <kd value="1.0"/>
    <fdir1 value="0 1 0"/>
  </gazebo>
  <link name="front_left_roller5_link">
    <visual>
      <origin rpy="0 0 0" xyz="0 0 0"/>
      <geometry>
        <mesh filename="file:///home/johnathan/devel/inspectobot/rosrover/install/mecanum_model/share/mecanum_model/meshes/visual/roller.dae" scale="0.001 0.001 0.001"/>
      </geometry>
    </visual>
    <collision>
      <geometry>
        <mesh filename="file:///home/johnathan/devel/inspectobot/rosrover/install/mecanum_model/share/mecanum_model/meshes/collision/roller.stl" scale="1 1 1"/>
      </geometry>
    </collision>
    <inertial>
      <origin xyz="0 0 0"/>
      <mass value="0.3"/>
      <inertia ixx="0.00024000" ixy="0.0" ixz="0.0" iyy="0.00076000" iyz="0.0" izz="0.00076000"/>
    </inertial>
  </link>
  <joint name="front_left_roller5_joint" type="continuous">
    <origin rpy="1.4966127917301504 0.07398025001120949 -0.7826515949744619" xyz="0 -0.0046776487312274965 0.04450485481773023"/>
    <parent link="front_left_wheel_link"/>
    <child link="front_left_roller5_link"/>
    <dynamics damping="0.001" friction="0.0001"/>
  </joint>
  <transmission name="${name}_roller5_trans">
    <type>transmission_interface/SimpleTransmission</type>
    <joint name="front_left_roller5_joint">
      <hardwareInterface>hardware_interface/EffortJointInterface</hardwareInterface>
    </joint>
    <actuator name="front_left_roller5_motor">
      <hardwareInterface>hardware_interface/EffortJointInterface</hardwareInterface>
      <mechanismReduction>1</mechanismReduction>
    </actuator>
  </transmission>
  <gazebo reference="front_left_roller5_link">
    <mu1 value="0.8"/>
    <mu2 value="0.8"/>
    <kp value="10000000.0"/>
    <kd value="1.0"/>
    <fdir1 value="0 1 0"/>
  </gazebo>
  <link name="front_left_roller4_link">
    <visual>
      <origin rpy="0 0 0" xyz="0 0 0"/>
      <geometry>
        <mesh filename="file:///home/johnathan/devel/inspectobot/rosrover/install/mecanum_model/share/mecanum_model/meshes/visual/roller.dae" scale="0.001 0.001 0.001"/>
      </geometry>
    </visual>
    <collision>
      <geometry>
        <mesh filename="file:///home/johnathan/devel/inspectobot/rosrover/install/mecanum_model/share/mecanum_model/meshes/collision/roller.stl" scale="1 1 1"/>
      </geometry>
    </collision>
    <inertial>
      <origin xyz="0 0 0"/>
      <mass value="0.3"/>
      <inertia ixx="0.00024000" ixy="0.0" ixz="0.0" iyy="0.00076000" iyz="0.0" izz="0.00076000"/>
    </inertial>
  </link>
  <joint name="front_left_roller4_joint" type="continuous">
    <origin rpy="-1.3449626171032882 -0.2202852738547472 -0.7603177925108144" xyz="0 0.013828510498278898 0.04255977910420812"/>
    <parent link="front_left_wheel_link"/>
    <child link="front_left_roller4_link"/>
    <dynamics damping="0.001" friction="0.0001"/>
  </joint>
  <transmission name="${name}_roller4_trans">
    <type>transmission_interface/SimpleTransmission</type>
    <joint name="front_left_roller4_joint">
      <hardwareInterface>hardware_interface/EffortJointInterface</hardwareInterface>
    </joint>
    <actuator name="front_left_roller4_motor">
      <hardwareInterface>hardware_interface/EffortJointInterface</hardwareInterface>
      <mechanismReduction>1</mechanismReduction>
    </actuator>
  </transmission>
  <gazebo reference="front_left_roller4_link">
    <mu1 value="0.8"/>
    <mu2 value="0.8"/>
    <kp value="10000000.0"/>
    <kd value="1.0"/>
    <fdir1 value="0 1 0"/>
  </gazebo>
  <link name="front_left_roller3_link">
    <visual>
      <origin rpy="0 0 0" xyz="0 0 0"/>
      <geometry>
        <mesh filename="file:///home/johnathan/devel/inspectobot/rosrover/install/mecanum_model/share/mecanum_model/meshes/visual/roller.dae" scale="0.001 0.001 0.001"/>
      </geometry>
    </visual>
    <collision>
      <geometry>
        <mesh filename="file:///home/johnathan/devel/inspectobot/rosrover/install/mecanum_model/share/mecanum_model/meshes/collision/roller.stl" scale="1 1 1"/>
      </geometry>
    </collision>
    <inertial>
      <origin xyz="0 0 0"/>
      <mass value="0.3"/>
      <inertia ixx="0.00024000" ixy="0.0" ixz="0.0" iyy="0.00076000" iyz="0.0" izz="0.00076000"/>
    </inertial>
  </link>
  <joint name="front_left_roller3_joint" type="continuous">
    <origin rpy="-1.0038406803226867 -0.4928592704898485 -0.6390993414905141" xyz="0 0.029943594634558906 0.033255730940113394"/>
    <parent link="front_left_wheel_link"/>
    <child link="front_left_roller3_link"/>
    <dynamics damping="0.001" friction="0.0001"/>
  </joint>
  <transmission name="${name}_roller3_trans">
    <type>transmission_interface/SimpleTransmission</type>
    <joint name="front_left_roller3_joint">
      <hardwareInterface>hardware_interface/EffortJointInterface</hardwareInterface>
    </joint>
    <actuator name="front_left_roller3_motor">
      <hardwareInterface>hardware_interface/EffortJointInterface</hardwareInterface>
      <mechanismReduction>1</mechanismReduction>
    </actuator>
  </transmission>
  <gazebo reference="front_left_roller3_link">
    <mu1 value="0.8"/>
    <mu2 value="0.8"/>
    <kp value="10000000.0"/>
    <kd value="1.0"/>
    <fdir1 value="0 1 0"/>
  </gazebo>
  <link name="front_left_roller2_link">
    <visual>
      <origin rpy="0 0 0" xyz="0 0 0"/>
      <geometry>
        <mesh filename="file:///home/johnathan/devel/inspectobot/rosrover/install/mecanum_model/share/mecanum_model/meshes/visual/roller.dae" scale="0.001 0.001 0.001"/>
      </geometry>
    </visual>
    <collision>
      <geometry>
        <mesh filename="file:///home/johnathan/devel/inspectobot/rosrover/install/mecanum_model/share/mecanum_model/meshes/collision/roller.stl" scale="1 1 1"/>
      </geometry>
    </collision>
    <inertial>
      <origin xyz="0 0 0"/>
      <mass value="0.3"/>
      <inertia ixx="0.00024000" ixy="0.0" ixz="0.0" iyy="0.00076000" iyz="0.0" izz="0.00076000"/>
    </inertial>
  </link>
  <joint name="front_left_roller2_joint" type="continuous">
    <origin rpy="-0.5619350361043128 -0.702298780729168 -0.3863003038769115" xyz="0 0.040881159229506386 0.01820146477764206"/>
    <parent link="front_left_wheel_link"/>
    <child link="front_left_roller2_link"/>
    <dynamics damping="0.001" friction="0.0001"/>
  </joint>
  <transmission name="${name}_roller2_trans">
    <type>transmission_interface/SimpleTransmission</type>
    <joint name="front_left_roller2_joint">
      <hardwareInterface>hardware_interface/EffortJointInterface</hardwareInterface>
    </joint>
    <actuator name="front_left_roller2_motor">
      <hardwareInterface>hardware_interface/EffortJointInterface</hardwareInterface>
      <mechanismReduction>1</mechanismReduction>
    </actuator>
  </transmission>
  <gazebo reference="front_left_roller2_link">
    <mu1 value="0.8"/>
    <mu2 value="0.8"/>
    <kp value="10000000.0"/>
    <kd value="1.0"/>
    <fdir1 value="0 1 0"/>
  </gazebo>
  <link name="front_left_roller1_link">
    <visual>
      <origin rpy="0 0 0" xyz="0 0 0"/>
      <geometry>
        <mesh filename="file:///home/johnathan/devel/inspectobot/rosrover/install/mecanum_model/share/mecanum_model/meshes/visual/roller.dae" scale="0.001 0.001 0.001"/>
      </geometry>
    </visual>
    <collision>
      <geometry>
        <mesh filename="file:///home/johnathan/devel/inspectobot/rosrover/install/mecanum_model/share/mecanum_model/meshes/collision/roller.stl" scale="1 1 1"/>
      </geometry>
    </collision>
    <inertial>
      <origin xyz="0 0 0"/>
      <mass value="0.3"/>
      <inertia ixx="0.00024000" ixy="0.0" ixz="0.0" iyy="0.00076000" iyz="0.0" izz="0.00076000"/>
    </inertial>
  </link>
  <joint name="front_left_roller1_joint" type="continuous">
    <origin rpy="-0.0 -0.7853981633974482 -0.0" xyz="0 0.04475 0.0"/>
    <parent link="front_left_wheel_link"/>
    <child link="front_left_roller1_link"/>
    <dynamics damping="0.001" friction="0.0001"/>
  </joint>
  <transmission name="${name}_roller1_trans">
    <type>transmission_interface/SimpleTransmission</type>
    <joint name="front_left_roller1_joint">
      <hardwareInterface>hardware_interface/EffortJointInterface</hardwareInterface>
    </joint>
    <actuator name="front_left_roller1_motor">
      <hardwareInterface>hardware_interface/EffortJointInterface</hardwareInterface>
      <mechanismReduction>1</mechanismReduction>
    </actuator>
  </transmission>
  <gazebo reference="front_left_roller1_link">
    <mu1 value="0.8"/>
    <mu2 value="0.8"/>
    <kp value="10000000.0"/>
    <kd value="1.0"/>
    <fdir1 value="0 1 0"/>
  </gazebo>
  <transmission name="front_left_wheel_trans">
    <type>transmission_interface/SimpleTransmission</type>
    <joint name="front_left_wheel_joint">
      <hardwareInterface>hardware_interface/EffortJointInterface</hardwareInterface>
    </joint>
    <actuator name="front_left_wheel_motor">
      <hardwareInterface>hardware_interface/EffortJointInterface</hardwareInterface>
      <mechanismReduction>1</mechanismReduction>
    </actuator>
  </transmission>
  <!-- <link name="wheel1">
    <visual>
      <origin xyz="0 0 0" rpy="0 0 0"/>
      <geometry>
      	<mesh filename="file://$(find mecanum_model)/meshes/visual/wheel_cw.stl" scale="0.001 0.001 0.001"/>
	     </geometry>
       <material name="light_grey" />
    </visual>
    <collision>
      <origin rpy="${PI/2} 0 0" xyz="0 0 0"/>
      <geometry>
        <cylinder length="${wheel_width}" radius="${wheel_radius}" />
      </geometry>
    </collision>
    <xacro:cylinder_inertia m="1.0" r="${wheel_radius}" h="${wheel_width}"/>
  </link> -->
  <joint name="wheel2_shaft_joint" type="continuous">
    <origin rpy="0 0 0" xyz="0.065 0.1 0.0"/>
    <axis xyz="1 0 0"/>
    <parent link="chassis"/>
    <child link="wheel2_shaft"/>
  </joint>
  <link name="wheel2_shaft">
    <visual>
      <origin rpy="0 0 0" xyz="0 0 0.0"/>
      <geometry>
        <mesh filename="file:///home/johnathan/devel/inspectobot/rosrover/install/mecanum_model/share/mecanum_model/meshes/visual/wheel_shaft_max.stl" scale="0.001 0.001 0.001"/>
      </geometry>
      <material name="black"/>
    </visual>
    <collision>
      <origin rpy="1.5707963267948966 0 0" xyz="0 0 0"/>
      <geometry>
        <cylinder length="0.037585724" radius="0.005"/>
      </geometry>
    </collision>
    <inertial>
      <origin rpy="1.5707963267948966 0 0" xyz="0 0 0"/>
      <mass value="1.0"/>
      <inertia ixx="0.00012397388738368133" ixy="0" ixz="0" iyy="0.00012397388738368133" iyz="0" izz="1.25e-05"/>
    </inertial>
  </link>
  <joint name="wheel2_wheel_joint" type="fixed">
    <origin rpy="0 0 0" xyz="0.035 0 0"/>
    <parent link="wheel2_shaft"/>
    <child link="wheel2"/>
  </joint>
  <link name="wheel2">
    <visual>
      <origin rpy="0 0 0" xyz="0 0 0"/>
      <geometry>
        <mesh filename="file:///home/johnathan/devel/inspectobot/rosrover/install/mecanum_model/share/mecanum_model/meshes/visual/wheel_ccw.stl" scale="0.001 0.001 0.001"/>
      </geometry>
      <material name="light_grey"/>
    </visual>
    <collision>
      <origin rpy="1.5707963267948966 0 0" xyz="0 0 0"/>
      <geometry>
        <cylinder length="0.045538024999999996" radius="0.051020508"/>
      </geometry>
    </collision>
    <inertial>
      <origin rpy="1.5707963267948966 0 0" xyz="0 0 0"/>
      <mass value="1.0"/>
      <inertia ixx="0.000823582369219568" ixy="0" ixz="0" iyy="0.000823582369219568" iyz="0" izz="0.001301546118289032"/>
    </inertial>
  </link>
  <joint name="wheel3_shaft_joint" type="continuous">
    <origin rpy="0 0 0" xyz="0.065 -0.1 0.0"/>
    <axis xyz="1 0 0"/>
    <parent link="chassis"/>
    <child link="wheel3_shaft"/>
  </joint>
  <link name="wheel3_shaft">
    <visual>
      <origin rpy="0 0 0" xyz="0 0 0.0"/>
      <geometry>
        <mesh filename="file:///home/johnathan/devel/inspectobot/rosrover/install/mecanum_model/share/mecanum_model/meshes/visual/wheel_shaft_max.stl" scale="0.001 0.001 0.001"/>
      </geometry>
      <material name="black"/>
    </visual>
    <collision>
      <origin rpy="1.5707963267948966 0 0" xyz="0 0 0"/>
      <geometry>
        <cylinder length="0.037585724" radius="0.005"/>
      </geometry>
    </collision>
    <inertial>
      <origin rpy="1.5707963267948966 0 0" xyz="0 0 0"/>
      <mass value="1.0"/>
      <inertia ixx="0.00012397388738368133" ixy="0" ixz="0" iyy="0.00012397388738368133" iyz="0" izz="1.25e-05"/>
    </inertial>
  </link>
  <joint name="wheel3_wheel_joint" type="fixed">
    <origin rpy="0 0 0" xyz="0.035 0 0"/>
    <parent link="wheel3_shaft"/>
    <child link="wheel3"/>
  </joint>
  <link name="wheel3">
    <visual>
      <origin rpy="0 0 3.141592653589793" xyz="0 0 0"/>
      <geometry>
        <mesh filename="file:///home/johnathan/devel/inspectobot/rosrover/install/mecanum_model/share/mecanum_model/meshes/visual/wheel_cw.stl" scale="0.001 0.001 0.001"/>
      </geometry>
      <material name="light_grey"/>
    </visual>
    <collision>
      <origin rpy="1.5707963267948966 0 0" xyz="0 0 0"/>
      <geometry>
        <cylinder length="0.045538024999999996" radius="0.051020508"/>
      </geometry>
    </collision>
    <inertial>
      <origin rpy="1.5707963267948966 0 0" xyz="0 0 0"/>
      <mass value="1.0"/>
      <inertia ixx="0.000823582369219568" ixy="0" ixz="0" iyy="0.000823582369219568" iyz="0" izz="0.001301546118289032"/>
    </inertial>
  </link>
  <joint name="wheel4_shaft_joint" type="continuous">
    <origin rpy="0 0 0" xyz="-0.065 -0.1 0.0"/>
    <axis xyz="1 0 0"/>
    <parent link="chassis"/>
    <child link="wheel4_shaft"/>
  </joint>
  <link name="wheel4_shaft">
    <visual>
      <origin rpy="0 0 0" xyz="0 0 0.0"/>
      <geometry>
        <mesh filename="file:///home/johnathan/devel/inspectobot/rosrover/install/mecanum_model/share/mecanum_model/meshes/visual/wheel_shaft_min.stl" scale="0.001 0.001 0.001"/>
      </geometry>
      <material name="black"/>
    </visual>
    <collision>
      <origin rpy="1.5707963267948966 0 0" xyz="0 0 0"/>
      <geometry>
        <cylinder length="0.037585724" radius="0.005"/>
      </geometry>
    </collision>
    <inertial>
      <origin rpy="1.5707963267948966 0 0" xyz="0 0 0"/>
      <mass value="1.0"/>
      <inertia ixx="0.00012397388738368133" ixy="0" ixz="0" iyy="0.00012397388738368133" iyz="0" izz="1.25e-05"/>
    </inertial>
  </link>
  <joint name="wheel4_wheel_joint" type="fixed">
    <origin rpy="0 0 0" xyz="-0.035 0 0"/>
    <parent link="wheel4_shaft"/>
    <child link="wheel4"/>
  </joint>
  <link name="wheel4">
    <visual>
      <origin rpy="0 0 3.141592653589793" xyz="0 0 0"/>
      <geometry>
        <mesh filename="file:///home/johnathan/devel/inspectobot/rosrover/install/mecanum_model/share/mecanum_model/meshes/visual/wheel_ccw.stl" scale="0.001 0.001 0.001"/>
      </geometry>
      <material name="light_grey"/>
    </visual>
    <collision>
      <origin rpy="1.5707963267948966 0 0" xyz="0 0 0"/>
      <geometry>
        <cylinder length="0.045538024999999996" radius="0.051020508"/>
      </geometry>
    </collision>
    <inertial>
      <origin rpy="1.5707963267948966 0 0" xyz="0 0 0"/>
      <mass value="1.0"/>
      <inertia ixx="0.000823582369219568" ixy="0" ixz="0" iyy="0.000823582369219568" iyz="0" izz="0.001301546118289032"/>
    </inertial>
  </link>
</robot>
